Workbook

Sheet Sheet1
A1: 2 | E1: 2 | F1: 15 | G1: 16 | H1: 20 | I1: 26 | J1: 33 | M1: =VLOOKUP(E1,A:A,1,FALSE) -> 2 | N1: =VLOOKUP(F1,$A:$A,1,FALSE) -> 15 | O1: =VLOOKUP(G1,$A:$A,1,FALSE) -> 16 | P1: =VLOOKUP(H1,$A:$A,1,FALSE) -> #N/A | Q1: =VLOOKUP(I1,$A:$A,1,FALSE) -> 26 | R1: =VLOOKUP(J1,$A:$A,1,FALSE) -> 33 | S1: =VLOOKUP(K1,$A:$A,1,FALSE) -> #N/A | T1: =VLOOKUP(L1,$A:$A,1,FALSE) -> #N/A | V1: 2 | W1: 15 | X1: 16 | Y1: #N/A | Z1: 26 | AA1: 33 | AD1: 111 | AE1: 15 | AF1: 16 | AG1: 21 | AH1: 26 | AI1: 33 | AL1: 5 | AM1: 9 | AN1: 13 | AO1: 16 | AP1: 24 | AQ1: 33 | AR1: DBP5 | AS1: MEX67 | AT1: NAB2 | AU1: PAB1 | AV1: SAC3 | AW1: YRA1 | AZ1: Gene Name | BA1: # | BB1: Gene Name
A2: 4 | E2: 2 | F2: 15 | G2: 16 | H2: 20 | I2: 26 | J2: 28 | M2: =VLOOKUP(E2,A:A,1,FALSE) -> 2 | N2: =VLOOKUP(F2,$A:$A,1,FALSE) -> 15 | O2: =VLOOKUP(G2,$A:$A,1,FALSE) -> 16 | P2: =VLOOKUP(H2,$A:$A,1,FALSE) -> #N/A | Q2: =VLOOKUP(I2,$A:$A,1,FALSE) -> 26 | R2: =VLOOKUP(J2,$A:$A,1,FALSE) -> 28 | S2: =VLOOKUP(K2,$A:$A,1,FALSE) -> #N/A | T2: =VLOOKUP(L2,$A:$A,1,FALSE) -> #N/A | V2: 2 | W2: 15 | X2: 16 | Y2: #N/A | Z2: 26 | AA2: 28 | AD2: 107 | AE2: 16 | AF2: 27 | AG2: 31 | AH2: 33 | AL2: 5 | AM2: 9 | AN2: 13 | AO2: 16 | AP2: 24 | AR2: DBP5 | AS2: MEX67 | AT2: NAB2 | AU2: PAB1 | AV2: SAC3 | AZ2: CBC2 | BA2: 1 | BB2: CBC2
A3: 5 | E3: 2 | F3: 15 | G3: 16 | H3: 19 | I3: 26 | J3: 33 | M3: =VLOOKUP(E3,A:A,1,FALSE) -> 2 | N3: =VLOOKUP(F3,$A:$A,1,FALSE) -> 15 | O3: =VLOOKUP(G3,$A:$A,1,FALSE) -> 16 | P3: =VLOOKUP(H3,$A:$A,1,FALSE) -> #N/A | Q3: =VLOOKUP(I3,$A:$A,1,FALSE) -> 26 | R3: =VLOOKUP(J3,$A:$A,1,FALSE) -> 33 | S3: =VLOOKUP(K3,$A:$A,1,FALSE) -> #N/A | T3: =VLOOKUP(L3,$A:$A,1,FALSE) -> #N/A | V3: 2 | W3: 15 | X3: 16 | Y3: #N/A | Z3: 26 | AA3: 33 | AD3: 101 | AE3: 6 | AF3: 15 | AG3: 16 | AH3: 31 | AI3: 33 | AL3: 2 | AM3: 15 | AN3: 16 | AO3: 26 | AP3: 28 | AR3: STO1 | AS3: NPL3 | AT3: PAB1 | AU3: SNU71 | AV3: SNU114 | AZ3: STO1 | BA3: 2 | BB3: STO1
A4: 6 | E4: 2 | F4: 15 | G4: 16 | H4: 31 | I4: 33 | M4: =VLOOKUP(E4,A:A,1,FALSE) -> 2 | N4: =VLOOKUP(F4,$A:$A,1,FALSE) -> 15 | O4: =VLOOKUP(G4,$A:$A,1,FALSE) -> 16 | P4: =VLOOKUP(H4,$A:$A,1,FALSE) -> 31 | Q4: =VLOOKUP(I4,$A:$A,1,FALSE) -> 33 | R4: =VLOOKUP(J4,$A:$A,1,FALSE) -> #N/A | S4: =VLOOKUP(K4,$A:$A,1,FALSE) -> #N/A | T4: =VLOOKUP(L4,$A:$A,1,FALSE) -> #N/A | V4: 2 | W4: 15 | X4: 16 | Y4: 31 | Z4: 33 | AA4: #N/A | AD4: 100 | AE4: 5 | AF4: 9 | AG4: 13 | AH4: 16 | AI4: 24 | AJ4: 33 | AL4: 5 | AM4: 7 | AN4: 13 | AO4: 16 | AP4: 33 | AR4: DBP5 | AS4: GFD1 | AT4: NAB2 | AU4: PAB1 | AV4: YRA1 | AZ4: CFT1 | BA4: 3 | BB4: CFT1
A5: 7 | E5: 2 | F5: 15 | G5: 16 | H5: 26 | I5: 28 | M5: =VLOOKUP(E5,A:A,1,FALSE) -> 2 | N5: =VLOOKUP(F5,$A:$A,1,FALSE) -> 15 | O5: =VLOOKUP(G5,$A:$A,1,FALSE) -> 16 | P5: =VLOOKUP(H5,$A:$A,1,FALSE) -> 26 | Q5: =VLOOKUP(I5,$A:$A,1,FALSE) -> 28 | R5: =VLOOKUP(J5,$A:$A,1,FALSE) -> #N/A | S5: =VLOOKUP(K5,$A:$A,1,FALSE) -> #N/A | T5: =VLOOKUP(L5,$A:$A,1,FALSE) -> #N/A | V5: 2 | W5: 15 | X5: 16 | Y5: 26 | Z5: 28 | AA5: #N/A | AD5: 99 | AE5: 16 | AF5: 21 | AG5: 29 | AH5: 33 | AL5: 5 | AM5: 9 | AN5: 13 | AO5: 16 | AP5: 33 | AR5: DBP5 | AS5: MEX67 | AT5: NAB2 | AU5: PAB1 | AV5: YRA1 | AZ5: CLP1 | BA5: 4 | BB5: CLP1
A6: 9 | E6: 2 | F6: 15 | G6: 16 | H6: 20 | I6: 33 | M6: =VLOOKUP(E6,A:A,1,FALSE) -> 2 | N6: =VLOOKUP(F6,$A:$A,1,FALSE) -> 15 | O6: =VLOOKUP(G6,$A:$A,1,FALSE) -> 16 | P6: =VLOOKUP(H6,$A:$A,1,FALSE) -> #N/A | Q6: =VLOOKUP(I6,$A:$A,1,FALSE) -> 33 | R6: =VLOOKUP(J6,$A:$A,1,FALSE) -> #N/A | S6: =VLOOKUP(K6,$A:$A,1,FALSE) -> #N/A | T6: =VLOOKUP(L6,$A:$A,1,FALSE) -> #N/A | V6: 2 | W6: 15 | X6: 16 | Y6: #N/A | Z6: 33 | AA6: #N/A | AD6: 98 | AE6: 9 | AF6: 13 | AG6: 16 | AH6: 27 | AI6: 33 | AL6: 4 | AM6: 13 | AN6: 15 | AO6: 16 | AP6: 33 | AR6: CLP1 | AS6: NAB2 | AT6: NPL3 | AU6: PAB1 | AV6: YRA1 | AZ6: DBP5 | BA6: 5 | BB6: DBP5
A7: 13 | E7: 2 | F7: 15 | G7: 16 | H7: 20 | I7: 26 | M7: =VLOOKUP(E7,A:A,1,FALSE) -> 2 | N7: =VLOOKUP(F7,$A:$A,1,FALSE) -> 15 | O7: =VLOOKUP(G7,$A:$A,1,FALSE) -> 16 | P7: =VLOOKUP(H7,$A:$A,1,FALSE) -> #N/A | Q7: =VLOOKUP(I7,$A:$A,1,FALSE) -> 26 | R7: =VLOOKUP(J7,$A:$A,1,FALSE) -> #N/A | S7: =VLOOKUP(K7,$A:$A,1,FALSE) -> #N/A | T7: =VLOOKUP(L7,$A:$A,1,FALSE) -> #N/A | V7: 2 | W7: 15 | X7: 16 | Y7: #N/A | Z7: 26 | AA7: #N/A | AD7: 97 | AE7: 7 | AF7: 15 | AG7: 16 | AH7: 26 | AI7: 33 | AL7: 7 | AM7: 13 | AN7: 15 | AO7: 16 | AP7: 33 | AR7: GFD1 | AS7: NAB2 | AT7: NPL3 | AU7: PAB1 | AV7: YRA1 | AZ7: GBP2 | BA7: 6 | BB7: GBP2
A8: 14 | E8: 2 | F8: 15 | G8: 16 | H8: 19 | I8: 33 | M8: =VLOOKUP(E8,A:A,1,FALSE) -> 2 | N8: =VLOOKUP(F8,$A:$A,1,FALSE) -> 15 | O8: =VLOOKUP(G8,$A:$A,1,FALSE) -> 16 | P8: =VLOOKUP(H8,$A:$A,1,FALSE) -> #N/A | Q8: =VLOOKUP(I8,$A:$A,1,FALSE) -> 33 | R8: =VLOOKUP(J8,$A:$A,1,FALSE) -> #N/A | S8: =VLOOKUP(K8,$A:$A,1,FALSE) -> #N/A | T8: =VLOOKUP(L8,$A:$A,1,FALSE) -> #N/A | V8: 2 | W8: 15 | X8: 16 | Y8: #N/A | Z8: 33 | AA8: #N/A | AD8: 97 | AE8: 2 | AF8: 15 | AG8: 16 | AH8: 31 | AI8: 33 | AL8: 4 | AM8: 15 | AN8: 16 | AO8: 21 | AP8: 33 | AR8: CLP1 | AS8: NPL3 | AT8: PAB1 | AU8: REF2 | AV8: YRA1 | AZ8: GFD1 | BA8: 7 | BB8: GFD1
A9: 15 | E9: 2 | F9: 20 | G9: 26 | H9: 28 | M9: =VLOOKUP(E9,A:A,1,FALSE) -> 2 | N9: =VLOOKUP(F9,$A:$A,1,FALSE) -> #N/A | O9: =VLOOKUP(G9,$A:$A,1,FALSE) -> 26 | P9: =VLOOKUP(H9,$A:$A,1,FALSE) -> 28 | Q9: =VLOOKUP(I9,$A:$A,1,FALSE) -> #N/A | R9: =VLOOKUP(J9,$A:$A,1,FALSE) -> #N/A | S9: =VLOOKUP(K9,$A:$A,1,FALSE) -> #N/A | T9: =VLOOKUP(L9,$A:$A,1,FALSE) -> #N/A | V9: 2 | W9: 26 | X9: 28 | Y9: #N/A | Z9: #N/A | AD9: 95 | AE9: 15 | AF9: 16 | AG9: 31 | AH9: 33 | AL9: 5 | AM9: 9 | AN9: 13 | AO9: 24 | AP9: 33 | AR9: DBP5 | AS9: MEX67 | AT9: NAB2 | AU9: SAC3 | AV9: YRA1 | AZ9: HRB1 | BA9: 8 | BB9: HRB1
A10: 16 | E10: 2 | F10: 16 | G10: 19 | H10: 33 | M10: =VLOOKUP(E10,A:A,1,FALSE) -> 2 | N10: =VLOOKUP(F10,$A:$A,1,FALSE) -> 16 | O10: =VLOOKUP(G10,$A:$A,1,FALSE) -> #N/A | P10: =VLOOKUP(H10,$A:$A,1,FALSE) -> 33 | Q10: =VLOOKUP(I10,$A:$A,1,FALSE) -> #N/A | R10: =VLOOKUP(J10,$A:$A,1,FALSE) -> #N/A | S10: =VLOOKUP(K10,$A:$A,1,FALSE) -> #N/A | T10: =VLOOKUP(L10,$A:$A,1,FALSE) -> #N/A | V10: 2 | W10: 16 | X10: 33 | Y10: #N/A | Z10: #N/A | AD10: 92 | AE10: 2 | AF10: 15 | AG10: 16 | AH10: 26 | AI10: 33 | AL10: 5 | AM10: 9 | AN10: 16 | AO10: 24 | AP10: 33 | AR10: DBP5 | AS10: MEX67 | AT10: PAB1 | AU10: SAC3 | AV10: YRA1 | AZ10: MEX67 | BA10: 9 | BB10: MEX67
A11: 21 | E11: 2 | F11: 15 | G11: 31 | H11: 33 | M11: =VLOOKUP(E11,A:A,1,FALSE) -> 2 | N11: =VLOOKUP(F11,$A:$A,1,FALSE) -> 15 | O11: =VLOOKUP(G11,$A:$A,1,FALSE) -> 31 | P11: =VLOOKUP(H11,$A:$A,1,FALSE) -> 33 | Q11: =VLOOKUP(I11,$A:$A,1,FALSE) -> #N/A | R11: =VLOOKUP(J11,$A:$A,1,FALSE) -> #N/A | S11: =VLOOKUP(K11,$A:$A,1,FALSE) -> #N/A | T11: =VLOOKUP(L11,$A:$A,1,FALSE) -> #N/A | V11: 2 | W11: 15 | X11: 31 | Y11: 33 | Z11: #N/A | AA11: #N/A | AD11: 91 | AE11: 5 | AF11: 13 | AG11: 16 | AH11: 24 | AI11: 33 | AL11: 5 | AM11: 13 | AN11: 16 | AO11: 24 | AP11: 33 | AR11: DBP5 | AS11: NAB2 | AT11: PAB1 | AU11: SAC3 | AV11: YRA1 | AZ11: MLP1 | BA11: 10 | BB11: MLP1
A12: 23 | E12: 2 | F12: 15 | G12: 20 | H12: 33 | M12: =VLOOKUP(E12,A:A,1,FALSE) -> 2 | N12: =VLOOKUP(F12,$A:$A,1,FALSE) -> 15 | O12: =VLOOKUP(G12,$A:$A,1,FALSE) -> #N/A | P12: =VLOOKUP(H12,$A:$A,1,FALSE) -> 33 | Q12: =VLOOKUP(I12,$A:$A,1,FALSE) -> #N/A | R12: =VLOOKUP(J12,$A:$A,1,FALSE) -> #N/A | S12: =VLOOKUP(K12,$A:$A,1,FALSE) -> #N/A | T12: =VLOOKUP(L12,$A:$A,1,FALSE) -> #N/A | V12: 2 | W12: 15 | X12: 33 | Y12: #N/A | Z12: #N/A | AD12: 89 | AE12: 4 | AF12: 15 | AG12: 16 | AH12: 21 | AI12: 33 | AL12: 2 | AM12: 15 | AN12: 16 | AO12: 26 | AP12: 33 | AR12: STO1 | AS12: NPL3 | AT12: PAB1 | AU12: SNU71 | AV12: YRA1 | AZ12: MLP2 | BA12: 11 | BB12: MLP2
A13: 24 | E13: 2 | F13: 15 | G13: 20 | H13: 28 | M13: =VLOOKUP(E13,A:A,1,FALSE) -> 2 | N13: =VLOOKUP(F13,$A:$A,1,FALSE) -> 15 | O13: =VLOOKUP(G13,$A:$A,1,FALSE) -> #N/A | P13: =VLOOKUP(H13,$A:$A,1,FALSE) -> 28 | Q13: =VLOOKUP(I13,$A:$A,1,FALSE) -> #N/A | R13: =VLOOKUP(J13,$A:$A,1,FALSE) -> #N/A | S13: =VLOOKUP(K13,$A:$A,1,FALSE) -> #N/A | T13: =VLOOKUP(L13,$A:$A,1,FALSE) -> #N/A | V13: 2 | W13: 15 | X13: 28 | Y13: #N/A | Z13: #N/A | AD13: 87 | AE13: 2 | AF13: 15 | AG13: 16 | AH13: 26 | AI13: 28 | AL13: 7 | AM13: 15 | AN13: 16 | AO13: 26 | AP13: 33 | AR13: GFD1 | AS13: NPL3 | AT13: PAB1 | AU13: SNU71 | AV13: YRA1 | AZ13: MTR2 | BA13: 12 | BB13: MTR2
A14: 26 | E14: 2 | F14: 15 | G14: 20 | H14: 26 | M14: =VLOOKUP(E14,A:A,1,FALSE) -> 2 | N14: =VLOOKUP(F14,$A:$A,1,FALSE) -> 15 | O14: =VLOOKUP(G14,$A:$A,1,FALSE) -> #N/A | P14: =VLOOKUP(H14,$A:$A,1,FALSE) -> 26 | Q14: =VLOOKUP(I14,$A:$A,1,FALSE) -> #N/A | R14: =VLOOKUP(J14,$A:$A,1,FALSE) -> #N/A | S14: =VLOOKUP(K14,$A:$A,1,FALSE) -> #N/A | T14: =VLOOKUP(L14,$A:$A,1,FALSE) -> #N/A | V14: 2 | W14: 15 | X14: 26 | Y14: #N/A | Z14: #N/A | AD14: 87 | AE14: 5 | AF14: 9 | AG14: 16 | AH14: 24 | AI14: 33 | AL14: 15 | AM14: 16 | AN14: 21 | AO14: 26 | AP14: 33 | AR14: NPL3 | AS14: PAB1 | AT14: REF2 | AU14: SNU71 | AV14: YRA1 | AZ14: NAB2 | BA14: 13 | BB14: NAB2
A15: 27 | E15: 2 | F15: 15 | G15: 16 | H15: 33 | M15: =VLOOKUP(E15,A:A,1,FALSE) -> 2 | N15: =VLOOKUP(F15,$A:$A,1,FALSE) -> 15 | O15: =VLOOKUP(G15,$A:$A,1,FALSE) -> 16 | P15: =VLOOKUP(H15,$A:$A,1,FALSE) -> 33 | Q15: =VLOOKUP(I15,$A:$A,1,FALSE) -> #N/A | R15: =VLOOKUP(J15,$A:$A,1,FALSE) -> #N/A | S15: =VLOOKUP(K15,$A:$A,1,FALSE) -> #N/A | T15: =VLOOKUP(L15,$A:$A,1,FALSE) -> #N/A | V15: 2 | W15: 15 | X15: 16 | Y15: 33 | Z15: #N/A | AA15: #N/A | AD15: 85 | AE15: 15 | AF15: 16 | AG15: 26 | AH15: 28 | AL15: 9 | AM15: 13 | AN15: 16 | AO15: 27 | AP15: 33 | AR15: MEX67 | AS15: NAB2 | AT15: PAB1 | AU15: SUB2 | AV15: YRA1 | AZ15: HRP1 | BA15: 14 | BB15: HRP1
A16: 28 | E16: 2 | F16: 15 | G16: 16 | H16: 31 | M16: =VLOOKUP(E16,A:A,1,FALSE) -> 2 | N16: =VLOOKUP(F16,$A:$A,1,FALSE) -> 15 | O16: =VLOOKUP(G16,$A:$A,1,FALSE) -> 16 | P16: =VLOOKUP(H16,$A:$A,1,FALSE) -> 31 | Q16: =VLOOKUP(I16,$A:$A,1,FALSE) -> #N/A | R16: =VLOOKUP(J16,$A:$A,1,FALSE) -> #N/A | S16: =VLOOKUP(K16,$A:$A,1,FALSE) -> #N/A | T16: =VLOOKUP(L16,$A:$A,1,FALSE) -> #N/A | V16: 2 | W16: 15 | X16: 16 | Y16: 31 | Z16: #N/A | AA16: #N/A | AD16: 85 | AE16: 15 | AF16: 16 | AG16: 21 | AH16: 33 | AL16: 2 | AM16: 15 | AN16: 16 | AO16: 31 | AP16: 33 | AR16: STO1 | AS16: NPL3 | AT16: PAB1 | AU16: THP2 | AV16: YRA1 | AZ16: NPL3 | BA16: 15 | BB16: NPL3
A17: 29 | E17: 2 | F17: 15 | G17: 16 | H17: 28 | M17: =VLOOKUP(E17,A:A,1,FALSE) -> 2 | N17: =VLOOKUP(F17,$A:$A,1,FALSE) -> 15 | O17: =VLOOKUP(G17,$A:$A,1,FALSE) -> 16 | P17: =VLOOKUP(H17,$A:$A,1,FALSE) -> 28 | Q17: =VLOOKUP(I17,$A:$A,1,FALSE) -> #N/A | R17: =VLOOKUP(J17,$A:$A,1,FALSE) -> #N/A | S17: =VLOOKUP(K17,$A:$A,1,FALSE) -> #N/A | T17: =VLOOKUP(L17,$A:$A,1,FALSE) -> #N/A | V17: 2 | W17: 15 | X17: 16 | Y17: 28 | Z17: #N/A | AA17: #N/A | AD17: 85 | AE17: 6 | AF17: 15 | AG17: 31 | AH17: 33 | AL17: 6 | AM17: 15 | AN17: 16 | AO17: 31 | AP17: 33 | AR17: GBP2 | AS17: NPL3 | AT17: PAB1 | AU17: THP2 | AV17: YRA1 | AZ17: PAB1 | BA17: 16 | BB17: PAB1
A18: 31 | E18: 2 | F18: 15 | G18: 16 | H18: 20 | M18: =VLOOKUP(E18,A:A,1,FALSE) -> 2 | N18: =VLOOKUP(F18,$A:$A,1,FALSE) -> 15 | O18: =VLOOKUP(G18,$A:$A,1,FALSE) -> 16 | P18: =VLOOKUP(H18,$A:$A,1,FALSE) -> #N/A | Q18: =VLOOKUP(I18,$A:$A,1,FALSE) -> #N/A | R18: =VLOOKUP(J18,$A:$A,1,FALSE) -> #N/A | S18: =VLOOKUP(K18,$A:$A,1,FALSE) -> #N/A | T18: =VLOOKUP(L18,$A:$A,1,FALSE) -> #N/A | V18: 2 | W18: 15 | X18: 16 | Y18: #N/A | Z18: #N/A | AA18: #N/A | AD18: 84 | AE18: 7 | AF18: 13 | AG18: 15 | AH18: 16 | AI18: 33 | AL18: 5 | AM18: 7 | AN18: 13 | AO18: 16 | AR18: DBP5 | AS18: GFD1 | AT18: NAB2 | AU18: PAB1 | AZ18: PAP1 | BA18: 17 | BB18: PAP1
A19: 33 | E19: 2 | F19: 33 | G19: 34 | M19: =VLOOKUP(E19,A:A,1,FALSE) -> 2 | N19: =VLOOKUP(F19,$A:$A,1,FALSE) -> 33 | O19: =VLOOKUP(G19,$A:$A,1,FALSE) -> #N/A | P19: =VLOOKUP(H19,$A:$A,1,FALSE) -> #N/A | Q19: =VLOOKUP(I19,$A:$A,1,FALSE) -> #N/A | R19: =VLOOKUP(J19,$A:$A,1,FALSE) -> #N/A | S19: =VLOOKUP(K19,$A:$A,1,FALSE) -> #N/A | T19: =VLOOKUP(L19,$A:$A,1,FALSE) -> #N/A | V19: 2 | W19: 33 | X19: #N/A | Y19: #N/A | Z19: #N/A | AA19: #N/A | AD19: 84 | AE19: 5 | AF19: 9 | AG19: 13 | AH19: 24 | AI19: 33 | AL19: 5 | AM19: 9 | AN19: 13 | AO19: 16 | AR19: DBP5 | AS19: MEX67 | AT19: NAB2 | AU19: PAB1 | AZ19: PML39 | BA19: 18 | BB19: PML39
A20: 64 | E20: 2 | F20: 20 | G20: 28 | M20: =VLOOKUP(E20,A:A,1,FALSE) -> 2 | N20: =VLOOKUP(F20,$A:$A,1,FALSE) -> #N/A | O20: =VLOOKUP(G20,$A:$A,1,FALSE) -> 28 | P20: =VLOOKUP(H20,$A:$A,1,FALSE) -> #N/A | Q20: =VLOOKUP(I20,$A:$A,1,FALSE) -> #N/A | R20: =VLOOKUP(J20,$A:$A,1,FALSE) -> #N/A | S20: =VLOOKUP(K20,$A:$A,1,FALSE) -> #N/A | T20: =VLOOKUP(L20,$A:$A,1,FALSE) -> #N/A | V20: 2 | W20: #N/A | X20: 28 | Y20: #N/A | Z20: #N/A | AA20: #N/A | AD20: 84 | AE20: 14 | AF20: 16 | AG20: 21 | AH20: 33 | AL20: 4 | AM20: 13 | AN20: 15 | AO20: 16 | AR20: CLP1 | AS20: NAB2 | AT20: NPL3 | AU20: PAB1 | AZ20: PRP42 | BA20: 19 | BB20: PRP42
E21: 2 | F21: 20 | G21: 26 | M21: =VLOOKUP(E21,A:A,1,FALSE) -> 2 | N21: =VLOOKUP(F21,$A:$A,1,FALSE) -> #N/A | O21: =VLOOKUP(G21,$A:$A,1,FALSE) -> 26 | P21: =VLOOKUP(H21,$A:$A,1,FALSE) -> #N/A | Q21: =VLOOKUP(I21,$A:$A,1,FALSE) -> #N/A | R21: =VLOOKUP(J21,$A:$A,1,FALSE) -> #N/A | S21: =VLOOKUP(K21,$A:$A,1,FALSE) -> #N/A | T21: =VLOOKUP(L21,$A:$A,1,FALSE) -> #N/A | V21: 2 | W21: #N/A | X21: 26 | Y21: #N/A | Z21: #N/A | AA21: #N/A | AD21: 83 | AE21: 21 | AF21: 29 | AG21: 33 | AL21: 7 | AM21: 13 | AN21: 15 | AO21: 16 | AR21: GFD1 | AS21: NAB2 | AT21: NPL3 | AU21: PAB1 | AZ21: PRP6 | BA21: 20 | BB21: PRP6
E22: 2 | F22: 19 | G22: 33 | M22: =VLOOKUP(E22,A:A,1,FALSE) -> 2 | N22: =VLOOKUP(F22,$A:$A,1,FALSE) -> #N/A | O22: =VLOOKUP(G22,$A:$A,1,FALSE) -> 33 | P22: =VLOOKUP(H22,$A:$A,1,FALSE) -> #N/A | Q22: =VLOOKUP(I22,$A:$A,1,FALSE) -> #N/A | R22: =VLOOKUP(J22,$A:$A,1,FALSE) -> #N/A | S22: =VLOOKUP(K22,$A:$A,1,FALSE) -> #N/A | T22: =VLOOKUP(L22,$A:$A,1,FALSE) -> #N/A | V22: 2 | W22: #N/A | X22: 33 | Y22: #N/A | Z22: #N/A | AA22: #N/A | AD22: 82 | AE22: 9 | AF22: 13 | AG22: 27 | AH22: 33 | AL22: 4 | AM22: 14 | AN22: 16 | AO22: 21 | AR22: CLP1 | AS22: HRP1 | AT22: PAB1 | AU22: REF2 | AZ22: REF2 | BA22: 21 | BB22: REF2
E23: 2 | F23: 16 | G23: 31 | M23: =VLOOKUP(E23,A:A,1,FALSE) -> 2 | N23: =VLOOKUP(F23,$A:$A,1,FALSE) -> 16 | O23: =VLOOKUP(G23,$A:$A,1,FALSE) -> 31 | P23: =VLOOKUP(H23,$A:$A,1,FALSE) -> #N/A | Q23: =VLOOKUP(I23,$A:$A,1,FALSE) -> #N/A | R23: =VLOOKUP(J23,$A:$A,1,FALSE) -> #N/A | S23: =VLOOKUP(K23,$A:$A,1,FALSE) -> #N/A | T23: =VLOOKUP(L23,$A:$A,1,FALSE) -> #N/A | V23: 2 | W23: 16 | X23: 31 | Y23: #N/A | Z23: #N/A | AA23: #N/A | AD23: 81 | AE23: 4 | AF23: 13 | AG23: 15 | AH23: 16 | AI23: 33 | AL23: 4 | AM23: 15 | AN23: 16 | AO23: 21 | AR23: CLP1 | AS23: NPL3 | AT23: PAB1 | AU23: REF2 | AZ23: RNA14 | BA23: 22 | BB23: RNA14
E24: 2 | F24: 15 | G24: 31 | M24: =VLOOKUP(E24,A:A,1,FALSE) -> 2 | N24: =VLOOKUP(F24,$A:$A,1,FALSE) -> 15 | O24: =VLOOKUP(G24,$A:$A,1,FALSE) -> 31 | P24: =VLOOKUP(H24,$A:$A,1,FALSE) -> #N/A | Q24: =VLOOKUP(I24,$A:$A,1,FALSE) -> #N/A | R24: =VLOOKUP(J24,$A:$A,1,FALSE) -> #N/A | S24: =VLOOKUP(K24,$A:$A,1,FALSE) -> #N/A | T24: =VLOOKUP(L24,$A:$A,1,FALSE) -> #N/A | V24: 2 | W24: 15 | X24: 31 | Y24: #N/A | Z24: #N/A | AA24: #N/A | AD24: 81 | AE24: 2 | AF24: 15 | AG24: 31 | AH24: 33 | AL24: 5 | AM24: 9 | AN24: 13 | AO24: 24 | AR24: DBP5 | AS24: MEX67 | AT24: NAB2 | AU24: SAC3 | AZ24: RRP6 | BA24: 23 | BB24: RRP6
E25: 2 | F25: 15 | G25: 16 | M25: =VLOOKUP(E25,A:A,1,FALSE) -> 2 | N25: =VLOOKUP(F25,$A:$A,1,FALSE) -> 15 | O25: =VLOOKUP(G25,$A:$A,1,FALSE) -> 16 | P25: =VLOOKUP(H25,$A:$A,1,FALSE) -> #N/A | Q25: =VLOOKUP(I25,$A:$A,1,FALSE) -> #N/A | R25: =VLOOKUP(J25,$A:$A,1,FALSE) -> #N/A | S25: =VLOOKUP(K25,$A:$A,1,FALSE) -> #N/A | T25: =VLOOKUP(L25,$A:$A,1,FALSE) -> #N/A | V25: 2 | W25: 15 | X25: 16 | Y25: #N/A | Z25: #N/A | AA25: #N/A | AD25: 79 | AE25: 15 | AF25: 31 | AG25: 33 | AL25: 5 | AM25: 9 | AN25: 16 | AO25: 24 | AR25: DBP5 | AS25: MEX67 | AT25: PAB1 | AU25: SAC3 | AZ25: SAC3 | BA25: 24 | BB25: SAC3
E26: 4 | F26: 15 | G26: 21 | H26: 22 | I26: 33 | J26: 35 | M26: =VLOOKUP(E26,A:A,1,FALSE) -> 4 | N26: =VLOOKUP(F26,$A:$A,1,FALSE) -> 15 | O26: =VLOOKUP(G26,$A:$A,1,FALSE) -> 21 | P26: =VLOOKUP(H26,$A:$A,1,FALSE) -> #N/A | Q26: =VLOOKUP(I26,$A:$A,1,FALSE) -> 33 | R26: =VLOOKUP(J26,$A:$A,1,FALSE) -> #N/A | S26: =VLOOKUP(K26,$A:$A,1,FALSE) -> #N/A | T26: =VLOOKUP(L26,$A:$A,1,FALSE) -> #N/A | V26: 2 | W26: 15 | X26: 16 | Y26: 26 | Z26: 33 | AD26: 78 | AE26: 15 | AF26: 16 | AG26: 21 | AH26: 26 | AL26: 5 | AM26: 13 | AN26: 16 | AO26: 24 | AR26: DBP5 | AS26: NAB2 | AT26: PAB1 | AU26: SAC3 | AZ26: SHE2 | BA26: 25 | BB26: SHE2
E27: 4 | F27: 15 | G27: 16 | H27: 21 | I27: 33 | J27: 35 | M27: =VLOOKUP(E27,A:A,1,FALSE) -> 4 | N27: =VLOOKUP(F27,$A:$A,1,FALSE) -> 15 | O27: =VLOOKUP(G27,$A:$A,1,FALSE) -> 16 | P27: =VLOOKUP(H27,$A:$A,1,FALSE) -> 21 | Q27: =VLOOKUP(I27,$A:$A,1,FALSE) -> 33 | R27: =VLOOKUP(J27,$A:$A,1,FALSE) -> #N/A | S27: =VLOOKUP(K27,$A:$A,1,FALSE) -> #N/A | T27: =VLOOKUP(L27,$A:$A,1,FALSE) -> #N/A | V27: 2 | W27: 15 | X27: 16 | Y27: 31 | Z27: 33 | AA27: #N/A | AD27: 78 | AE27: 5 | AF27: 16 | AG27: 24 | AH27: 33 | AL27: 2 | AM27: 15 | AN27: 16 | AO27: 26 | AR27: STO1 | AS27: NPL3 | AT27: PAB1 | AU27: SNU71 | AZ27: SNU71 | BA27: 26 | BB27: SNU71
E28: 4 | F28: 14 | G28: 16 | H28: 21 | I28: 33 | J28: 35 | M28: =VLOOKUP(E28,A:A,1,FALSE) -> 4 | N28: =VLOOKUP(F28,$A:$A,1,FALSE) -> 14 | O28: =VLOOKUP(G28,$A:$A,1,FALSE) -> 16 | P28: =VLOOKUP(H28,$A:$A,1,FALSE) -> 21 | Q28: =VLOOKUP(I28,$A:$A,1,FALSE) -> 33 | R28: =VLOOKUP(J28,$A:$A,1,FALSE) -> #N/A | S28: =VLOOKUP(K28,$A:$A,1,FALSE) -> #N/A | T28: =VLOOKUP(L28,$A:$A,1,FALSE) -> #N/A | V28: 2 | W28: 15 | X28: 16 | Y28: 26 | Z28: 33 | AA28: #N/A | AD28: 78 | AE28: 16 | AF28: 29 | AG28: 33 | AL28: 7 | AM28: 15 | AN28: 16 | AO28: 26 | AR28: GFD1 | AS28: NPL3 | AT28: PAB1 | AU28: SNU71 | AZ28: SUB2 | BA28: 27 | BB28: SUB2
E29: 4 | F29: 15 | G29: 16 | H29: 21 | I29: 35 | M29: =VLOOKUP(E29,A:A,1,FALSE) -> 4 | N29: =VLOOKUP(F29,$A:$A,1,FALSE) -> 15 | O29: =VLOOKUP(G29,$A:$A,1,FALSE) -> 16 | P29: =VLOOKUP(H29,$A:$A,1,FALSE) -> 21 | Q29: =VLOOKUP(I29,$A:$A,1,FALSE) -> #N/A | R29: =VLOOKUP(J29,$A:$A,1,FALSE) -> #N/A | S29: =VLOOKUP(K29,$A:$A,1,FALSE) -> #N/A | T29: =VLOOKUP(L29,$A:$A,1,FALSE) -> #N/A | V29: 2 | W29: 15 | X29: 16 | Y29: 26 | Z29: 28 | AA29: #N/A | AD29: 76 | AE29: 5 | AF29: 9 | AG29: 13 | AH29: 16 | AI29: 33 | AL29: 15 | AM29: 16 | AN29: 21 | AO29: 26 | AR29: NPL3 | AS29: PAB1 | AT29: REF2 | AU29: SNU71 | AZ29: SNU114 | BA29: 28 | BB29: SNU114
E30: 4 | F30: 15 | G30: 16 | H30: 21 | I30: 33 | M30: =VLOOKUP(E30,A:A,1,FALSE) -> 4 | N30: =VLOOKUP(F30,$A:$A,1,FALSE) -> 15 | O30: =VLOOKUP(G30,$A:$A,1,FALSE) -> 16 | P30: =VLOOKUP(H30,$A:$A,1,FALSE) -> 21 | Q30: =VLOOKUP(I30,$A:$A,1,FALSE) -> 33 | R30: =VLOOKUP(J30,$A:$A,1,FALSE) -> #N/A | S30: =VLOOKUP(K30,$A:$A,1,FALSE) -> #N/A | T30: =VLOOKUP(L30,$A:$A,1,FALSE) -> #N/A | V30: 2 | W30: 15 | X30: 16 | Y30: 33 | Z30: #N/A | AD30: 76 | AE30: 16 | AF30: 27 | AG30: 33 | AL30: 9 | AM30: 13 | AN30: 16 | AO30: 27 | AR30: MEX67 | AS30: NAB2 | AT30: PAB1 | AU30: SUB2 | AZ30: SYC1 | BA30: 29 | BB30: SYC1
E31: 4 | F31: 14 | G31: 21 | H31: 22 | I31: 35 | M31: =VLOOKUP(E31,A:A,1,FALSE) -> 4 | N31: =VLOOKUP(F31,$A:$A,1,FALSE) -> 14 | O31: =VLOOKUP(G31,$A:$A,1,FALSE) -> 21 | P31: =VLOOKUP(H31,$A:$A,1,FALSE) -> #N/A | Q31: =VLOOKUP(I31,$A:$A,1,FALSE) -> #N/A | R31: =VLOOKUP(J31,$A:$A,1,FALSE) -> #N/A | S31: =VLOOKUP(K31,$A:$A,1,FALSE) -> #N/A | T31: =VLOOKUP(L31,$A:$A,1,FALSE) -> #N/A | V31: 2 | W31: 15 | X31: #N/A | Y31: 26 | Z31: #N/A | AA31: #N/A | AD31: 74 | AE31: 5 | AF31: 7 | AG31: 13 | AH31: 16 | AI31: 33 | AL31: 2 | AM31: 15 | AN31: 16 | AO31: 28 | AR31: STO1 | AS31: NPL3 | AT31: PAB1 | AU31: SNU114 | AZ31: THP1 | BA31: 30 | BB31: THP1
E32: 4 | F32: 14 | G32: 16 | H32: 21 | I32: 35 | M32: =VLOOKUP(E32,A:A,1,FALSE) -> 4 | N32: =VLOOKUP(F32,$A:$A,1,FALSE) -> 14 | O32: =VLOOKUP(G32,$A:$A,1,FALSE) -> 16 | P32: =VLOOKUP(H32,$A:$A,1,FALSE) -> 21 | Q32: =VLOOKUP(I32,$A:$A,1,FALSE) -> #N/A | R32: =VLOOKUP(J32,$A:$A,1,FALSE) -> #N/A | S32: =VLOOKUP(K32,$A:$A,1,FALSE) -> #N/A | T32: =VLOOKUP(L32,$A:$A,1,FALSE) -> #N/A | V32: 2 | W32: 15 | X32: 16 | Y32: 33 | Z32: #N/A | AA32: #N/A | AD32: 74 | AE32: 4 | AF32: 16 | AG32: 21 | AH32: 33 | AL32: 15 | AM32: 16 | AN32: 26 | AO32: 28 | AR32: NPL3 | AS32: PAB1 | AT32: SNU71 | AU32: SNU114 | AZ32: THP2 | BA32: 31 | BB32: THP2
E33: 4 | F33: 13 | G33: 15 | H33: 16 | I33: 33 | M33: =VLOOKUP(E33,A:A,1,FALSE) -> 4 | N33: =VLOOKUP(F33,$A:$A,1,FALSE) -> 13 | O33: =VLOOKUP(G33,$A:$A,1,FALSE) -> 15 | P33: =VLOOKUP(H33,$A:$A,1,FALSE) -> 16 | Q33: =VLOOKUP(I33,$A:$A,1,FALSE) -> 33 | R33: =VLOOKUP(J33,$A:$A,1,FALSE) -> #N/A | S33: =VLOOKUP(K33,$A:$A,1,FALSE) -> #N/A | T33: =VLOOKUP(L33,$A:$A,1,FALSE) -> #N/A | V33: 2 | W33: 15 | X33: 16 | Y33: 31 | Z33: #N/A | AA33: #N/A | AD33: 74 | AE33: 16 | AF33: 27 | AG33: 31 | AL33: 2 | AM33: 15 | AN33: 16 | AO33: 31 | AR33: STO1 | AS33: NPL3 | AT33: PAB1 | AU33: THP2 | AZ33: YHR127W | BA33: 32 | BB33: YHR127W
E34: 4 | F34: 16 | G34: 21 | H34: 33 | M34: =VLOOKUP(E34,A:A,1,FALSE) -> 4 | N34: =VLOOKUP(F34,$A:$A,1,FALSE) -> 16 | O34: =VLOOKUP(G34,$A:$A,1,FALSE) -> 21 | P34: =VLOOKUP(H34,$A:$A,1,FALSE) -> 33 | Q34: =VLOOKUP(I34,$A:$A,1,FALSE) -> #N/A | R34: =VLOOKUP(J34,$A:$A,1,FALSE) -> #N/A | S34: =VLOOKUP(K34,$A:$A,1,FALSE) -> #N/A | T34: =VLOOKUP(L34,$A:$A,1,FALSE) -> #N/A | V34: 2 | W34: 15 | X34: 16 | Y34: 28 | Z34: #N/A | AA34: #N/A | AD34: 73 | AE34: 4 | AF34: 15 | AG34: 21 | AH34: 33 | AL34: 6 | AM34: 15 | AN34: 16 | AO34: 31 | AR34: GBP2 | AS34: NPL3 | AT34: PAB1 | AU34: THP2 | AZ34: YRA1 | BA34: 33 | BB34: YRA1
E35: 4 | F35: 16 | G35: 17 | H35: 21 | M35: =VLOOKUP(E35,A:A,1,FALSE) -> 4 | N35: =VLOOKUP(F35,$A:$A,1,FALSE) -> 16 | O35: =VLOOKUP(G35,$A:$A,1,FALSE) -> #N/A | P35: =VLOOKUP(H35,$A:$A,1,FALSE) -> 21 | Q35: =VLOOKUP(I35,$A:$A,1,FALSE) -> #N/A | R35: =VLOOKUP(J35,$A:$A,1,FALSE) -> #N/A | S35: =VLOOKUP(K35,$A:$A,1,FALSE) -> #N/A | T35: =VLOOKUP(L35,$A:$A,1,FALSE) -> #N/A | V35: 2 | W35: 15 | X35: 16 | Y35: 26 | Z35: #N/A | AA35: #N/A | AD35: 73 | AE35: 13 | AF35: 27 | AG35: 33 | AL35: 5 | AM35: 7 | AN35: 13 | AO35: 33 | AR35: DBP5 | AS35: GFD1 | AT35: NAB2 | AU35: YRA1 | AZ35: YRA2 | BA35: 34 | BB35: YRA2
E36: 4 | F36: 15 | G36: 16 | H36: 21 | M36: =VLOOKUP(E36,A:A,1,FALSE) -> 4 | N36: =VLOOKUP(F36,$A:$A,1,FALSE) -> 15 | O36: =VLOOKUP(G36,$A:$A,1,FALSE) -> 16 | P36: =VLOOKUP(H36,$A:$A,1,FALSE) -> 21 | Q36: =VLOOKUP(I36,$A:$A,1,FALSE) -> #N/A | R36: =VLOOKUP(J36,$A:$A,1,FALSE) -> #N/A | S36: =VLOOKUP(K36,$A:$A,1,FALSE) -> #N/A | T36: =VLOOKUP(L36,$A:$A,1,FALSE) -> #N/A | V36: 2 | W36: 15 | X36: 16 | Y36: #N/A | Z36: #N/A | AA36: #N/A | AD36: 73 | AE36: 16 | AF36: 24 | AG36: 33 | AL36: 5 | AM36: 9 | AN36: 13 | AO36: 33 | AR36: DBP5 | AS36: MEX67 | AT36: NAB2 | AU36: YRA1 | AZ36: YSH1 | BA36: 35 | BB36: YSH1
E37: 4 | F37: 15 | G37: 16 | H37: 17 | M37: =VLOOKUP(E37,A:A,1,FALSE) -> 4 | N37: =VLOOKUP(F37,$A:$A,1,FALSE) -> 15 | O37: =VLOOKUP(G37,$A:$A,1,FALSE) -> 16 | P37: =VLOOKUP(H37,$A:$A,1,FALSE) -> #N/A | Q37: =VLOOKUP(I37,$A:$A,1,FALSE) -> #N/A | R37: =VLOOKUP(J37,$A:$A,1,FALSE) -> #N/A | S37: =VLOOKUP(K37,$A:$A,1,FALSE) -> #N/A | T37: =VLOOKUP(L37,$A:$A,1,FALSE) -> #N/A | V37: 2 | W37: 26 | X37: 33 | Y37: #N/A | Z37: #N/A | AA37: #N/A | AD37: 72 | AE37: 16 | AF37: 23 | AG37: 33 | AL37: 4 | AM37: 13 | AN37: 15 | AO37: 33 | AR37: CLP1 | AS37: NAB2 | AT37: NPL3 | AU37: YRA1 | AZ37: NSP1 | BA37: 36 | BB37: NSP1
E38: 4 | F38: 14 | G38: 16 | H38: 21 | M38: =VLOOKUP(E38,A:A,1,FALSE) -> 4 | N38: =VLOOKUP(F38,$A:$A,1,FALSE) -> 14 | O38: =VLOOKUP(G38,$A:$A,1,FALSE) -> 16 | P38: =VLOOKUP(H38,$A:$A,1,FALSE) -> 21 | Q38: =VLOOKUP(I38,$A:$A,1,FALSE) -> #N/A | R38: =VLOOKUP(J38,$A:$A,1,FALSE) -> #N/A | S38: =VLOOKUP(K38,$A:$A,1,FALSE) -> #N/A | T38: =VLOOKUP(L38,$A:$A,1,FALSE) -> #N/A | V38: 2 | W38: 26 | X38: 28 | Y38: #N/A | Z38: #N/A | AA38: #N/A | AD38: 71 | AE38: 7 | AF38: 15 | AG38: 16 | AH38: 33 | AL38: 5 | AM38: 7 | AN38: 16 | AO38: 33 | AR38: DBP5 | AS38: GFD1 | AT38: PAB1 | AU38: YRA1 | AZ38: NUP159 | BA38: 37 | BB38: NUP159
E39: 4 | F39: 13 | G39: 16 | H39: 33 | M39: =VLOOKUP(E39,A:A,1,FALSE) -> 4 | N39: =VLOOKUP(F39,$A:$A,1,FALSE) -> 13 | O39: =VLOOKUP(G39,$A:$A,1,FALSE) -> 16 | P39: =VLOOKUP(H39,$A:$A,1,FALSE) -> 33 | Q39: =VLOOKUP(I39,$A:$A,1,FALSE) -> #N/A | R39: =VLOOKUP(J39,$A:$A,1,FALSE) -> #N/A | S39: =VLOOKUP(K39,$A:$A,1,FALSE) -> #N/A | T39: =VLOOKUP(L39,$A:$A,1,FALSE) -> #N/A | V39: 2 | W39: 15 | X39: 16 | Y39: #N/A | Z39: #N/A | AA39: #N/A | AD39: 71 | AE39: 9 | AF39: 13 | AG39: 16 | AH39: 33 | AL39: 5 | AM39: 9 | AN39: 16 | AO39: 33 | AR39: DBP5 | AS39: MEX67 | AT39: PAB1 | AU39: YRA1 | AZ39: NIC96 | BA39: 38 | BB39: NIC96
E40: 4 | F40: 13 | G40: 15 | H40: 33 | M40: =VLOOKUP(E40,A:A,1,FALSE) -> 4 | N40: =VLOOKUP(F40,$A:$A,1,FALSE) -> 13 | O40: =VLOOKUP(G40,$A:$A,1,FALSE) -> 15 | P40: =VLOOKUP(H40,$A:$A,1,FALSE) -> 33 | Q40: =VLOOKUP(I40,$A:$A,1,FALSE) -> #N/A | R40: =VLOOKUP(J40,$A:$A,1,FALSE) -> #N/A | S40: =VLOOKUP(K40,$A:$A,1,FALSE) -> #N/A | T40: =VLOOKUP(L40,$A:$A,1,FALSE) -> #N/A | V40: 4 | W40: 15 | X40: 21 | Y40: #N/A | Z40: 33 | AA40: #N/A | AD40: 71 | AE40: 5 | AF40: 9 | AG40: 24 | AH40: 33 | AL40: 4 | AM40: 13 | AN40: 16 | AO40: 33 | AR40: CLP1 | AS40: NAB2 | AT40: PAB1 | AU40: YRA1 | AZ40: NUP188 | BA40: 39 | BB40: NUP188
...

Sheet no nested cliques
A1: 5 | B1: 9 | C1: 13 | D1: 16 | E1: 24 | F1: 33 | G1: DBP5 | H1: MEX67 | I1: NAB2 | J1: PAB1 | K1: SAC3 | L1: YRA1 | O1: 16 | P1: 20 | T1: DBP5 | W1: 5 | Z1: CBC2 | AA1: 1 | AC1: CBC2 | AD1: 1 | AE1: CBC2 | AF1: 0 | AH1: CBC2 | AJ1: process | AK1: node | AL1: node degree | AM1: # of cliques | AN1: process | AQ1: process | AR1: process | AS1: node | AT1: node degree | AU1: # of cliques | AV1: # | AZ1: process | BA1: node | BB1: node degree | BC1: # of cliques | BD1: #
A2: 2 | B2: 15 | C2: 16 | D2: 26 | E2: 28 | G2: STO1 | H2: NPL3 | I2: PAB1 | J2: SNU71 | K2: SNU114 | O2: 33 | P2: 17 | T2: STO1 | W2: 2 | Z2: CDC33 | AA2: 2 | AC2: STO1 | AD2: 2 | AE2: STO1 | AF2: 4 | AH2: CFT1 | AJ2: Polyadenylation | AK2: NAB2 | AL2: 55 | AM2: 5 | AN2: =VLOOKUP(AK2,'general process'!D:E,2,FALSE) -> Polyadenylation | AQ2: 5'end -CBC | AR2: 5'end -CBC | AS2: CBC2 | AT2: 14 | AU2: 0 | AV2: 1 | AZ2: 5'end-CBC | BA2: CBC2 | BB2: 14 | BC2: 0 | BD2: 1
A3: 5 | B3: 7 | C3: 13 | D3: 16 | E3: 33 | G3: DBP5 | H3: GFD1 | I3: NAB2 | J3: PAB1 | K3: YRA1 | O3: 15 | P3: 10 | T3: CLP1 | W3: 4 | Z3: CFT1 | AA3: 3 | AC3: CFT1 | AD3: 3 | AE3: CFT1 | AF3: 0 | AH3: CLP1 | AJ3: Polyadenylation | AK3: PAB1 | AL3: 47 | AM3: 20 | AN3: =VLOOKUP(AK3,'general process'!D:E,2,FALSE) -> Polyadenylation | AQ3: 5'end -CBC | AS3: STO1 | AT3: 15 | AU3: 4 | AV3: 2 | BA3: STO1 | BB3: 15 | BC3: 4 | BD3: 2
A4: 4 | B4: 13 | C4: 15 | D4: 16 | E4: 33 | G4: CLP1 | H4: NAB2 | I4: NPL3 | J4: PAB1 | K4: YRA1 | O4: 13 | P4: 5 | T4: GFD1 | W4: 7 | Z4: CLP1 | AA4: 4 | AC4: CLP1 | AD4: 4 | AE4: CLP1 | AF4: 4 | AH4: DBP5 | AJ4: Co-transcriptional THO | AK4: YRA1 | AL4: 46 | AM4: 17 | AN4: =VLOOKUP(AK4,'general process'!D:E,2,FALSE) -> Co-transcriptional THO | AQ4: Co-transcriptional THO | AR4: Co-transcriptional THO | AS4: THP2 | AT4: 15 | AU4: 3 | AV4: 4 | AZ4: Co-transcriptional; THO | BA4: THP2 | BB4: 15 | BC4: 3 | BD4: 4
A5: 7 | B5: 13 | C5: 15 | D5: 16 | E5: 33 | G5: GFD1 | H5: NAB2 | I5: NPL3 | J5: PAB1 | K5: YRA1 | O5: 21 | P5: 5 | T5: MEX67 | W5: 9 | Z5: DBP5 | AA5: 5 | AC5: DBP5 | AD5: 5 | AE5: DBP5 | AF5: 2 | AH5: GBP2 | AJ5: Polyadenylation | AK5: NPL3 | AL5: 35 | AM5: 10 | AN5: =VLOOKUP(AK5,'general process'!D:E,2,FALSE) -> Polyadenylation | AQ5: Co-transcriptional THO | AS5: YRA1 | AT5: 46 | AU5: 17 | AV5: 5 | BA5: YRA1 | BB5: 46 | BC5: 17 | BD5: 5
A6: 4 | B6: 15 | C6: 16 | D6: 21 | E6: 33 | G6: CLP1 | H6: NPL3 | I6: PAB1 | J6: REF2 | K6: YRA1 | O6: 2 | P6: 4 | T6: GBP2 | W6: 6 | Z6: GBP2 | AA6: 6 | AC6: GBP2 | AD6: 6 | AE6: GBP2 | AF6: 2 | AH6: GFD1 | AJ6: TREX | AK6: SUB2 | AL6: 21 | AM6: 2 | AN6: =VLOOKUP(AK6,'general process'!D:E,2,FALSE) -> TREX | AQ6: Co-transcriptional THO | AS6: YHR127W | AT6: 8 | AU6: 0 | AV6: 6 | BA6: YHR127W | BB6: 8 | BC6: 0 | BD6: 6
A7: 2 | B7: 15 | C7: 16 | D7: 26 | E7: 33 | G7: STO1 | H7: NPL3 | I7: PAB1 | J7: SNU71 | K7: YRA1 | O7: 4 | P7: 4 | T7: NPL3 | W7: 15 | Z7: GFD1 | AA7: 7 | AC7: GFD1 | AD7: 7 | AE7: GFD1 | AF7: 3 | AH7: HRB1 | AJ7: 3'end processing | AK7: REF2 | AL7: 19 | AM7: 5 | AN7: =VLOOKUP(AK7,'general process'!D:E,2,FALSE) -> 3'end processing | AQ7: Co-transcriptional THO | AS7: YRA2 | AT7: 4 | AU7: 0 | AV7: 7 | BA7: YRA2 | BB7: 4 | BC7: 0 | BD7: 7
A8: 7 | B8: 15 | C8: 16 | D8: 26 | E8: 33 | G8: GFD1 | H8: NPL3 | I8: PAB1 | J8: SNU71 | K8: YRA1 | O8: 14 | P8: 4 | T8: HRP1 | W8: 14 | Z8: HRB1 | AA8: 8 | AC8: HRB1 | AD8: 8 | AE8: HRB1 | AF8: 0 | AH8: HRP1 | AJ8: Quality control | AK8: PML39 | AL8: 19 | AM8: 0 | AN8: =VLOOKUP(AK8,'general process'!D:E,2,FALSE) -> Quality control | AQ8: Splicing | AR8: Splicing | AS8: SNU71 | AT8: 13 | AU8: 4 | AV8: 8 | AZ8: Splicing | BA8: SNU71 | BB8: 13 | BC8: 4 | BD8: 8
A9: 9 | B9: 13 | C9: 16 | D9: 27 | E9: 33 | G9: MEX67 | H9: NAB2 | I9: PAB1 | J9: SUB2 | K9: YRA1 | O9: 26 | P9: 4 | T9: PAB1 | W9: 16 | Z9: HRP1 | AA9: 9 | AC9: MEX67 | AD9: 9 | AE9: MEX67 | AF9: 2 | AH9: MEX67 | AJ9: Polyadenylation | AK9: GFD1 | AL9: 16 | AM9: 3 | AN9: =VLOOKUP(AK9,'general process'!D:E,2,FALSE) -> Polyadenylation | AQ9: Splicing | AS9: PRP42 | AT9: 7 | AU9: 0 | AV9: 9 | BA9: PRP42 | BB9: 7 | BC9: 0 | BD9: 9
A10: 2 | B10: 15 | C10: 16 | D10: 31 | E10: 33 | G10: STO1 | H10: NPL3 | I10: PAB1 | J10: THP2 | K10: YRA1 | O10: 7 | P10: 3 | T10: NAB2 | W10: 13 | Z10: MEX67 | AA10: 10 | AC10: MLP1 | AD10: 10 | AE10: MLP1 | AF10: 0 | AH10: MLP1 | AJ10: 3'end processing | AK10: CLP1 | AL10: 15 | AM10: 4 | AN10: =VLOOKUP(AK10,'general process'!D:E,2,FALSE) -> 3'end processing | AQ10: Splicing | AS10: SNU114 | AT10: 9 | AU10: 2 | AV10: 10 | BA10: SNU114 | BB10: 9 | BC10: 2 | BD10: 10
A11: 6 | B11: 15 | C11: 16 | D11: 31 | E11: 33 | G11: GBP2 | H11: NPL3 | I11: PAB1 | J11: THP2 | K11: YRA1 | O11: 31 | P11: 3 | T11: REF2 | W11: 21 | Z11: MLP1 | AA11: 11 | AC11: MLP2 | AD11: 11 | AE11: MLP2 | AF11: 0 | AH11: MLP2 | AJ11: 3'end processing | AK11: HRP1 | AL11: 15 | AM11: 4 | AN11: =VLOOKUP(AK11,'general process'!D:E,2,FALSE) -> 3'end processing | AQ11: Splicing | AS11: PRP6 | AT11: 8 | AU11: 0 | AV11: 11 | BA11: PRP6 | BB11: 8 | BC11: 0 | BD11: 11
A12: 15 | B12: 16 | C12: 21 | D12: 26 | E12: 33 | G12: NPL3 | H12: PAB1 | I12: REF2 | J12: SNU71 | K12: YRA1 | O12: 5 | P12: 2 | T12: SUB2 | W12: 27 | Z12: MLP2 | AA12: 12 | AC12: MTR2 | AD12: 12 | AE12: MTR2 | AF12: 0 | AH12: MTR2 | AJ12: 5'end -CBC | AK12: STO1 | AL12: 15 | AM12: 4 | AN12: =VLOOKUP(AK12,'general process'!D:E,2,FALSE) -> 5'end -CBC | AQ12: 3'end processing | AR12: 3'end processing | AS12: RNA14 | AT12: 14 | AU12: 0 | AV12: 12 | AZ12: 3'end processing | BA12: RNA14 | BB12: 14 | BC12: 0 | BD12: 12
A13: 4 | B13: 14 | C13: 16 | D13: 21 | G13: CLP1 | H13: HRP1 | I13: PAB1 | J13: REF2 | O13: 6 | P13: 2 | T13: RRP6 | W13: 23 | Z13: MTR2 | AA13: 13 | AC13: NAB2 | AD13: 13 | AE13: NAB2 | AF13: 5 | AH13: NAB2 | AJ13: Co-transcriptional THO | AK13: THP2 | AL13: 15 | AM13: 3 | AN13: =VLOOKUP(AK13,'general process'!D:E,2,FALSE) -> Co-transcriptional THO | AQ13: 3'end processing | AS13: CLP1 | AT13: 15 | AU13: 4 | AV13: 13 | BA13: CLP1 | BB13: 15 | BC13: 4 | BD13: 13
A14: 2 | B14: 15 | C14: 16 | D14: 28 | G14: STO1 | H14: NPL3 | I14: PAB1 | J14: SNU114 | O14: 9 | P14: 2 | T14: SYC1 | W14: 29 | Z14: NAB2 | AA14: 14 | AC14: HRP1 | AD14: 14 | AE14: HRP1 | AF14: 4 | AH14: NPL3 | AJ14: 5'end -CBC | AK14: CBC2 | AL14: 14 | AM14: 0 | AN14: =VLOOKUP(AK14,'general process'!D:E,2,FALSE) -> 5'end -CBC | AQ14: 3'end processing | AS14: YSH1 | AT14: 14 | AU14: 0 | AV14: 14 | BA14: YSH1 | BB14: 14 | BC14: 0 | BD14: 14
A15: 4 | B15: 14 | C15: 16 | D15: 33 | G15: CLP1 | H15: HRP1 | I15: PAB1 | J15: YRA1 | O15: 27 | P15: 2 | T15: THP2 | W15: 31 | Z15: NPL3 | AA15: 15 | AC15: NPL3 | AD15: 15 | AE15: NPL3 | AF15: 10 | AH15: PAB1 | AJ15: 3'end processing | AK15: CFT1 | AL15: 14 | AM15: 0 | AN15: =VLOOKUP(AK15,'general process'!D:E,2,FALSE) -> 3'end processing | AQ15: 3'end processing | AS15: HRP1 | AT15: 15 | AU15: 4 | AV15: 15 | BA15: HRP1 | BB15: 15 | BC15: 4 | BD15: 15
A16: 6 | B16: 14 | C16: 16 | D16: 33 | G16: GBP2 | H16: HRP1 | I16: PAB1 | J16: YRA1 | O16: 28 | P16: 2 | T16: YRA1 | W16: 33 | Z16: PAB1 | AA16: 16 | AC16: PAB1 | AD16: 16 | AE16: PAB1 | AF16: 20 | AH16: PAP1 | AJ16: 3'end processing | AK16: RNA14 | AL16: 14 | AM16: 0 | AN16: =VLOOKUP(AK16,'general process'!D:E,2,FALSE) -> 3'end processing | AQ16: 3'end processing | AS16: SYC1 | AT16: 4 | AU16: 1 | AV16: 16 | BA16: SYC1 | BB16: 4 | BC16: 1 | BD16: 16
A17: 14 | B17: 16 | C17: 21 | D17: 33 | G17: HRP1 | H17: PAB1 | I17: REF2 | J17: YRA1 | O17: 23 | P17: 1 | T17: SNU71 | W17: 26 | Z17: PAP1 | AA17: 17 | AC17: PAP1 | AD17: 17 | AE17: PAP1 | AF17: 0 | AH17: PML39 | AJ17: 3'end processing | AK17: YSH1 | AL17: 14 | AM17: 0 | AN17: =VLOOKUP(AK17,'general process'!D:E,2,FALSE) -> 3'end processing | AQ17: 3'end processing | AS17: CFT1 | AT17: 14 | AU17: 0 | AV17: 17 | BA17: CFT1 | BB17: 14 | BC17: 0 | BD17: 17
A18: 16 | B18: 21 | C18: 29 | D18: 33 | G18: PAB1 | H18: REF2 | I18: SYC1 | J18: YRA1 | O18: 24 | P18: 1 | T18: SNU114 | W18: 28 | Z18: PML39 | AA18: 18 | AC18: PML39 | AD18: 18 | AE18: PML39 | AF18: 0 | AH18: PRP42 | AJ18: Splicing | AK18: SNU71 | AL18: 13 | AM18: 4 | AN18: =VLOOKUP(AK18,'general process'!D:E,2,FALSE) -> Splicing | AQ18: 3'end processing | AS18: REF2 | AT18: 19 | AU18: 5 | AV18: 19 | BA18: REF2 | BB18: 19 | BC18: 5 | BD18: 19
A19: 16 | B19: 27 | C19: 31 | D19: 33 | G19: PAB1 | H19: SUB2 | I19: THP2 | J19: YRA1 | O19: 29 | P19: 1 | T19: SAC3 | W19: 24 | Z19: PRP42 | AA19: 19 | AC19: PRP42 | AD19: 19 | AE19: PRP42 | AF19: 0 | AH19: PRP6 | AJ19: Export | AK19: MEX67 | AL19: 13 | AM19: 2 | AN19: =VLOOKUP(AK19,'general process'!D:E,2,FALSE) -> Export | AQ19: Polyadenylation | AR19: Polyadenylation | AS19: PAB1 | AT19: 47 | AU19: 20 | AV19: 20 | AZ19: Polyadenylation | BA19: PAB1 | BB19: 47 | BC19: 20 | BD19: 20
A20: 16 | B20: 23 | C20: 33 | G20: PAB1 | H20: RRP6 | I20: YRA1 | Z20: PRP6 | AA20: 20 | AC20: PRP6 | AD20: 20 | AE20: PRP6 | AF20: 0 | AH20: REF2 | AJ20: Export | AK20: MLP1 | AL20: 13 | AM20: 0 | AN20: =VLOOKUP(AK20,'general process'!D:E,2,FALSE) -> Export | AQ20: Polyadenylation | AS20: PAP1 | AT20: 9 | AU20: 0 | AV20: 21 | BA20: PAP1 | BB20: 9 | BC20: 0 | BD20: 21
Z21: REF2 | AA21: 21 | AC21: REF2 | AD21: 21 | AE21: REF2 | AF21: 5 | AH21: RNA14 | AJ21: Export | AK21: MLP2 | AL21: 12 | AM21: 0 | AN21: =VLOOKUP(AK21,'general process'!D:E,2,FALSE) -> Export | AQ21: Polyadenylation | AS21: NAB2 | AT21: 55 | AU21: 5 | AV21: 22 | BA21: NAB2 | BB21: 55 | BC21: 5 | BD21: 22
Z22: RNA14 | AA22: 22 | AC22: RNA14 | AD22: 22 | AE22: RNA14 | AF22: 0 | AH22: RRP6 | AJ22: Export | AK22: DBP5 | AL22: 11 | AM22: 2 | AN22: =VLOOKUP(AK22,'general process'!D:E,2,FALSE) -> Export | AQ22: Polyadenylation | AS22: NPL3 | AT22: 35 | AU22: 10 | AV22: 23 | BA22: NPL3 | BB22: 35 | BC22: 10 | BD22: 23
Z23: RRP6 | AA23: 23 | AC23: RRP6 | AD23: 23 | AE23: RRP6 | AF23: 1 | AH23: SAC3 | AJ23: NPC associated | AK23: SAC3 | AL23: 10 | AM23: 1 | AN23: =VLOOKUP(AK23,'general process'!D:E,2,FALSE) -> NPC associated | AQ23: Polyadenylation | AS23: GBP2 | AT23: 7 | AU23: 2 | AV23: 24 | BA23: GBP2 | BB23: 7 | BC23: 2 | BD23: 24
Z24: SAC3 | AA24: 24 | AC24: SAC3 | AD24: 24 | AE24: SAC3 | AF24: 1 | AH24: SHE2 | AJ24: Polyadenylation | AK24: HRB1 | AL24: 10 | AM24: 0 | AN24: =VLOOKUP(AK24,'general process'!D:E,2,FALSE) -> Polyadenylation | AQ24: Polyadenylation | AS24: HRB1 | AT24: 10 | AU24: 0 | AV24: 25 | BA24: HRB1 | BB24: 10 | BC24: 0 | BD24: 25
Z25: SHE2 | AA25: 25 | AC25: SHE2 | AD25: 25 | AE25: SHE2 | AF25: 0 | AH25: SNU114 | AJ25: Splicing | AK25: SNU114 | AL25: 9 | AM25: 2 | AN25: =VLOOKUP(AK25,'general process'!D:E,2,FALSE) -> Splicing | AQ25: Polyadenylation | AS25: GFD1 | AT25: 16 | AU25: 3 | AV25: 26 | BA25: GFD1 | BB25: 16 | BC25: 3 | BD25: 26
Z26: SNU114 | AA26: 26 | AC26: SNU71 | AD26: 26 | AE26: SNU71 | AF26: 4 | AH26: SNU71 | AJ26: Polyadenylation | AK26: PAP1 | AL26: 9 | AM26: 0 | AN26: =VLOOKUP(AK26,'general process'!D:E,2,FALSE) -> Polyadenylation | AQ26: Degradation | AR26: Degradation | AS26: RRP6 | AT26: 3 | AU26: 1 | AV26: 27 | AZ26: D | BA26: Degradation RRP6 | BB26: 3 | BC26: 1 | BD26: 27
Z27: SNU71 | AA27: 27 | AC27: SUB2 | AD27: 27 | AE27: SUB2 | AF27: 2 | AH27: STO1 | AJ27: Splicing | AK27: PRP6 | AL27: 8 | AM27: 0 | AN27: =VLOOKUP(AK27,'general process'!D:E,2,FALSE) -> Splicing | AQ27: TREX | AR27: TREX | AS27: SUB2 | AT27: 21 | AU27: 2 | AV27: 28 | AZ27: T | BA27: TREX SUB2 | BB27: 21 | BC27: 2 | BD27: 28
Z28: STO1 | AA28: 28 | AC28: SNU114 | AD28: 28 | AE28: SNU114 | AF28: 2 | AH28: SUB2 | AJ28: Co-transcriptional THO | AK28: YHR127W | AL28: 8 | AM28: 0 | AN28: =VLOOKUP(AK28,'general process'!D:E,2,FALSE) -> Co-transcriptional THO | AQ28: Quality control | AR28: Quality control | AS28: PML39 | AT28: 19 | AU28: 0 | AV28: 29 | AZ28: QC | BA28: Quality control PML39 | BB28: 19 | BC28: 0 | BD28: 29
Z29: SUB2 | AA29: 29 | AC29: SYC1 | AD29: 29 | AE29: SYC1 | AF29: 1 | AH29: SYC1 | AJ29: Polyadenylation | AK29: GBP2 | AL29: 7 | AM29: 2 | AN29: =VLOOKUP(AK29,'general process'!D:E,2,FALSE) -> Polyadenylation | AQ29: NPC associated | AR29: NPC associated | AS29: SAC3 | AT29: 10 | AU29: 1 | AV29: 30 | AZ29: NPC associated | BA29: SAC3 | BB29: 10 | BC29: 1 | BD29: 30
Z30: SYC1 | AA30: 30 | AC30: THP1 | AD30: 30 | AE30: THP1 | AF30: 0 | AH30: THP1 | AJ30: Splicing | AK30: PRP42 | AL30: 7 | AM30: 0 | AN30: =VLOOKUP(AK30,'general process'!D:E,2,FALSE) -> Splicing | AQ30: NPC associated | AS30: THP1 | AT30: 3 | AU30: 0 | AV30: 31 | BA30: THP1 | BB30: 3 | BC30: 0 | BD30: 31
Z31: THP1 | AA31: 31 | AC31: THP2 | AD31: 31 | AE31: THP2 | AF31: 3 | AH31: THP2 | AJ31: 3'end processing | AK31: SYC1 | AL31: 4 | AM31: 1 | AN31: =VLOOKUP(AK31,'general process'!D:E,2,FALSE) -> 3'end processing | AQ31: Export | AR31: Export | AS31: MTR2 | AT31: 4 | AU31: 0 | AV31: 32 | AZ31: Export | BA31: MTR2 | BB31: 4 | BC31: 0 | BD31: 32
Z32: THP2 | AA32: 32 | AC32: YHR127W | AD32: 32 | AE32: YHR127W | AF32: 0 | AH32: YHR127W | AJ32: Export | AK32: MTR2 | AL32: 4 | AM32: 0 | AN32: =VLOOKUP(AK32,'general process'!D:E,2,FALSE) -> Export | AQ32: Export | AS32: MEX67 | AT32: 13 | AU32: 2 | AV32: 33 | BA32: MEX67 | BB32: 13 | BC32: 2 | BD32: 33
Z33: YHR127W | AA33: 33 | AC33: YRA1 | AD33: 33 | AE33: YRA1 | AF33: 17 | AH33: YRA1 | AJ33: Co-transcriptional THO | AK33: YRA2 | AL33: 4 | AM33: 0 | AN33: =VLOOKUP(AK33,'general process'!D:E,2,FALSE) -> Co-transcriptional THO | AQ33: Export | AS33: DBP5 | AT33: 11 | AU33: 2 | AV33: 34 | BA33: DBP5 | BB33: 11 | BC33: 2 | BD33: 34
Z34: YRA1 | AA34: 34 | AC34: YRA2 | AD34: 34 | AE34: YRA2 | AF34: 0 | AH34: YRA2 | AJ34: Degradation | AK34: RRP6 | AL34: 3 | AM34: 1 | AN34: =VLOOKUP(AK34,'general process'!D:E,2,FALSE) -> Degradation | AQ34: Export | AS34: MLP1 | AT34: 13 | AU34: 0 | AV34: 35 | BA34: MLP1 | BB34: 13 | BC34: 0 | BD34: 35
Z35: YRA2 | AA35: 35 | AC35: YSH1 | AD35: 35 | AE35: YSH1 | AF35: 0 | AH35: YSH1 | AJ35: NPC associated | AK35: THP1 | AL35: 3 | AM35: 0 | AN35: =VLOOKUP(AK35,'general process'!D:E,2,FALSE) -> NPC associated | AQ35: Export | AS35: MLP2 | AT35: 12 | AU35: 0 | AV35: 36 | BA35: MLP2 | BB35: 12 | BC35: 0 | BD35: 36
Z36: YSH1 | AA36: 36 | AJ36: Cytoplasmic mRNPs | AK36: SHE2 | AL36: 2 | AM36: 0 | AN36: =VLOOKUP(AK36,'general process'!D:E,2,FALSE) -> Cytoplasmic mRNPs | AQ36: Cytoplasmic mRNPs | AR36: Cytoplasmic mRNPs | AS36: SHE2 | AT36: 2 | AU36: 0 | AV36: 38 | AZ36: C | BA36: Cytoplasmic mRNPs SHE2 | BB36: 2 | BC36: 0 | BD36: 38

Sheet intra-interactome
A1: n1 | B1: n2 | C1: N1 | D1: N2 | E1: loop | G1: no loops | H1: N1 | I1: N2
A2: Nab2p | B2: Cbc2p | C2: NAB2 | D2: CBC2 | E2: 0 | H2: NAB2 | I2: CBC2
A3: Npl3p | B3: Cbc2p | C3: NPL3 | D3: CBC2 | E3: 0 | H3: NPL3 | I3: CBC2
A4: Snu114p | B4: Cbc2p | C4: SNU114 | D4: CBC2 | E4: 0 | H4: SNU114 | I4: CBC2
A5: Sto1p | B5: Cbc2p | C5: STO1 | D5: CBC2 | E5: 0 | H5: STO1 | I5: CBC2
A6: Clp1p | B6: Cft1p | C6: CLP1 | D6: CFT1 | E6: 0 | H6: CLP1 | I6: CFT1
A7: Hrp1p | B7: Cft1p | C7: HRP1 | D7: CFT1 | E7: 0 | H7: HRP1 | I7: CFT1
A8: Ref2p | B8: Cft1p | C8: REF2 | D8: CFT1 | E8: 0 | H8: REF2 | I8: CFT1
A9: Rna14p | B9: Cft1p | C9: RNA14 | D9: CFT1 | E9: 0 | H9: RNA14 | I9: CFT1
A10: Ysh1p | B10: Cft1p | C10: YSH1 | D10: CFT1 | E10: 0 | H10: YSH1 | I10: CFT1
A11: Cft1p | B11: Clp1p | C11: CFT1 | D11: CLP1 | E11: 0 | H11: CFT1 | I11: CLP1
A12: Hrp1p | B12: Clp1p | C12: HRP1 | D12: CLP1 | E12: 0 | H12: HRP1 | I12: CLP1
A13: Ref2p | B13: Clp1p | C13: REF2 | D13: CLP1 | E13: 0 | H13: REF2 | I13: CLP1
... A263: Rna14p | B263: Ysh1p | C263: RNA14 | D263: YSH1 | E263: 0 | H263: RNA14 | I263: YSH1
A264: Cbc2p | B264: Cbc2p | C264: CBC2 | D264: CBC2 | E264: 1
A265: Cft1p | B265: Cft1p | C265: CFT1 | D265: CFT1 | E265: 1
A266: Clp1p | B266: Clp1p | C266: CLP1 | D266: CLP1 | E266: 1
A267: Dbp5p | B267: Dbp5p | C267: DBP5 | D267: DBP5 | E267: 1
A268: Gfd1p | B268: Gfd1p | C268: GFD1 | D268: GFD1 | E268: 1
A269: Hrb1p | B269: Hrb1p | C269: HRB1 | D269: HRB1 | E269: 1
A270: Hrp1p | B270: Hrp1p | C270: HRP1 | D270: HRP1 | E270: 1
A271: Mex67p | B271: Mex67p | C271: MEX67 | D271: MEX67 | E271: 1
A272: Mlp1p | B272: Mlp1p | C272: MLP1 | D272: MLP1 | E272: 1
A273: Mlp2p | B273: Mlp2p | C273: MLP2 | D273: MLP2 | E273: 1
A274: Nab2p | B274: Nab2p | C274: NAB2 | D274: NAB2 | E274: 1
A275: Npl3p | B275: Npl3p | C275: NPL3 | D275: NPL3 | E275: 1
... A299: Ysh1p | B299: Ysh1p | C299: YSH1 | D299: YSH1 | E299: 1

Sheet general process
A1: # | B1: # | C1: bait | D1: gene | E1: process | G1: #
A2: 1 | B2: 1 | C2: Cbp20 | D2: CBC2 | E2: 5'end -CBC | F2: =VLOOKUP(D2,'no nested cliques'!AH:AH,1,FALSE) -> CBC2 | G2: 1
A3: 2 | B3: 2 | C3: Cbp80 | D3: STO1 | E3: 5'end -CBC | F3: =VLOOKUP(D3,'no nested cliques'!AH:AH,1,FALSE) -> STO1 | G3: 2
A4: 3 | B4: 3 | C4: Mft1 | D4: MFT1 | E4: Co-transcriptional THO | F4: =VLOOKUP(D4,'no nested cliques'!AH:AH,1,FALSE) -> #N/A | G4: 3
A5: 4 | B5: 4 | C5: Thp2 | D5: THP2 | E5: Co-transcriptional THO | F5: =VLOOKUP(D5,'no nested cliques'!AH:AH,1,FALSE) -> THP2 | G5: 4
A6: 5 | B6: 5 | C6: Yra1 | D6: YRA1 | E6: Co-transcriptional THO | F6: =VLOOKUP(D6,'no nested cliques'!AH:AH,1,FALSE) -> YRA1 | G6: 5
A7: 6 | B7: 6 | C7: Yhr127w | D7: YHR127W | E7: Co-transcriptional THO | F7: =VLOOKUP(D7,'no nested cliques'!AH:AH,1,FALSE) -> YHR127W | G7: 6
A8: 7 | B8: 7 | C8: Yra2 | D8: YRA2 | E8: Co-transcriptional THO | F8: =VLOOKUP(D8,'no nested cliques'!AH:AH,1,FALSE) -> YRA2 | G8: 7
A9: 8 | B9: 8 | C9: Snu71 | D9: SNU71 | E9: Splicing | F9: =VLOOKUP(D9,'no nested cliques'!AH:AH,1,FALSE) -> SNU71 | G9: 8
A10: 9 | B10: 9 | C10: Prp42 | D10: PRP42 | E10: Splicing | F10: =VLOOKUP(D10,'no nested cliques'!AH:AH,1,FALSE) -> PRP42 | G10: 9
A11: 10 | B11: 10 | C11: Snu114 | D11: SNU114 | E11: Splicing | F11: =VLOOKUP(D11,'no nested cliques'!AH:AH,1,FALSE) -> SNU114 | G11: 10
A12: 11 | B12: 11 | C12: Prp6 | D12: PRP6 | E12: Splicing | F12: =VLOOKUP(D12,'no nested cliques'!AH:AH,1,FALSE) -> PRP6 | G12: 11
A13: 12 | B13: 12 | C13: Rna14 | D13: RNA14 | E13: 3'end processing | F13: =VLOOKUP(D13,'no nested cliques'!AH:AH,1,FALSE) -> RNA14 | G13: 12
... A17: 10 | B17: 16 | C17: Syc1 | D17: SYC1 | E17: 3'end processing | F17: =VLOOKUP(D17,'no nested cliques'!AH:AH,1,FALSE) -> SYC1 | G17: 16
B18: 17 | C18: Cft1 | D18: CFT1 | E18: 3'end processing | F18: =VLOOKUP(D18,'no nested cliques'!AH:AH,1,FALSE) -> CFT1 | G18: 17
A19: 16 | B19: 18 | C19: Cft2 | D19: CFT2 | E19: 3'end processing | F19: =VLOOKUP(D19,'no nested cliques'!AH:AH,1,FALSE) -> #N/A | G19: 18
A20: 17 | B20: 19 | C20: Ref2 | D20: REF2 | E20: 3'end processing | F20: =VLOOKUP(D20,'no nested cliques'!AH:AH,1,FALSE) -> REF2 | G20: 19
A21: 18 | B21: 20 | C21: Pab1 | D21: PAB1 | E21: Polyadenylation | F21: =VLOOKUP(D21,'no nested cliques'!AH:AH,1,FALSE) -> PAB1 | G21: 20
A22: 19 | B22: 21 | C22: Pap1 | D22: PAP1 | E22: Polyadenylation | F22: =VLOOKUP(D22,'no nested cliques'!AH:AH,1,FALSE) -> PAP1 | G22: 21
A23: 20 | B23: 22 | C23: Nab2 | D23: NAB2 | E23: Polyadenylation | F23: =VLOOKUP(D23,'no nested cliques'!AH:AH,1,FALSE) -> NAB2 | G23: 22
A24: 21 | B24: 23 | C24: Npl3 | D24: NPL3 | E24: Polyadenylation | F24: =VLOOKUP(D24,'no nested cliques'!AH:AH,1,FALSE) -> NPL3 | G24: 23
A25: 22 | B25: 24 | C25: Gbp2 | D25: GBP2 | E25: Polyadenylation | F25: =VLOOKUP(D25,'no nested cliques'!AH:AH,1,FALSE) -> GBP2 | G25: 24
A26: 23 | B26: 25 | C26: Hrb1 | D26: HRB1 | E26: Polyadenylation | F26: =VLOOKUP(D26,'no nested cliques'!AH:AH,1,FALSE) -> HRB1 | G26: 25
A27: 24 | B27: 26 | C27: Gfd1 | D27: GFD1 | E27: Polyadenylation | F27: =VLOOKUP(D27,'no nested cliques'!AH:AH,1,FALSE) -> GFD1 | G27: 26
A28: 25 | B28: 27 | C28: Rrp6 | D28: RRP6 | E28: Degradation | F28: =VLOOKUP(D28,'no nested cliques'!AH:AH,1,FALSE) -> RRP6 | G28: 27
A29: 26 | B29: 28 | C29: Sub2 | D29: SUB2 | E29: TREX | F29: =VLOOKUP(D29,'no nested cliques'!AH:AH,1,FALSE) -> SUB2 | G29: 28
B30: 29 | C30: Pml39 | D30: PML39 | E30: Quality control | F30: =VLOOKUP(D30,'no nested cliques'!AH:AH,1,FALSE) -> PML39 | G30: 29
A31: 27 | B31: 30 | C31: Sac3 | D31: SAC3 | E31: NPC associated | F31: =VLOOKUP(D31,'no nested cliques'!AH:AH,1,FALSE) -> SAC3 | G31: 30
A32: 28 | B32: 31 | C32: Thp1 | D32: THP1 | E32: NPC associated | F32: =VLOOKUP(D32,'no nested cliques'!AH:AH,1,FALSE) -> THP1 | G32: 31
A33: 29 | B33: 32 | C33: Mtr2 | D33: MTR2 | E33: Export | F33: =VLOOKUP(D33,'no nested cliques'!AH:AH,1,FALSE) -> MTR2 | G33: 32
A34: 30 | B34: 33 | C34: Mex67 | D34: MEX67 | E34: Export | F34: =VLOOKUP(D34,'no nested cliques'!AH:AH,1,FALSE) -> MEX67 | G34: 33
A35: 31 | B35: 34 | C35: Dbp5 | D35: DBP5 | E35: Export | F35: =VLOOKUP(D35,'no nested cliques'!AH:AH,1,FALSE) -> DBP5 | G35: 34
A36: 32 | B36: 35 | C36: Mlp1 | D36: MLP1 | E36: Export | F36: =VLOOKUP(D36,'no nested cliques'!AH:AH,1,FALSE) -> MLP1 | G36: 35
A37: 33 | B37: 36 | C37: Mlp2 | D37: MLP2 | E37: Export | F37: =VLOOKUP(D37,'no nested cliques'!AH:AH,1,FALSE) -> MLP2 | G37: 36
A38: 34 | B38: 37 | C38: Cdc33/eIF4E | D38: CDC33 | E38: Cytoplasmic mRNPs | F38: =VLOOKUP(D38,'no nested cliques'!AH:AH,1,FALSE) -> #N/A | G38: 37
A39: 35 | B39: 38 | C39: She2 | D39: SHE2 | E39: Cytoplasmic mRNPs | F39: =VLOOKUP(D39,'no nested cliques'!AH:AH,1,FALSE) -> SHE2 | G39: 38

Sheet co-process
A1: not nested cliques | G1: general processes | P1: process | Q1: process | R1: node | S1: node degree | T1: # of cliques
A2: DBP5 | B2: MEX67 | C2: NAB2 | D2: PAB1 | E2: SAC3 | F2: YRA1 | G2: Export | H2: Export | I2: Polyadenylation | J2: Polyadenylation | K2: NPC associated | L2: Co-transcriptional THO | P2: 5'end -CBC | Q2: 5'end -CBC | R2: CBC2 | S2: 14 | T2: 0
A3: STO1 | B3: NPL3 | C3: PAB1 | D3: SNU71 | E3: SNU114 | G3: 5'end -CBC | H3: Polyadenylation | I3: Polyadenylation | J3: Splicing | K3: Splicing | P3: 5'end -CBC | R3: STO1 | S3: 15 | T3: 4
A4: DBP5 | B4: GFD1 | C4: NAB2 | D4: PAB1 | E4: YRA1 | G4: Export | H4: Polyadenylation | I4: Polyadenylation | J4: Polyadenylation | K4: Co-transcriptional THO | P4: Co-transcriptional THO | Q4: Co-transcriptional THO | R4: THP2 | S4: 15 | T4: 3
A5: CLP1 | B5: NAB2 | C5: NPL3 | D5: PAB1 | E5: YRA1 | G5: 3'end processing | H5: Polyadenylation | I5: Polyadenylation | J5: Polyadenylation | K5: Co-transcriptional THO | P5: Co-transcriptional THO | R5: YRA1 | S5: 46 | T5: 17
A6: GFD1 | B6: NAB2 | C6: NPL3 | D6: PAB1 | E6: YRA1 | G6: Polyadenylation | H6: Polyadenylation | I6: Polyadenylation | J6: Polyadenylation | K6: Co-transcriptional THO | P6: Co-transcriptional THO | R6: YHR127W | S6: 8 | T6: 0
A7: CLP1 | B7: NPL3 | C7: PAB1 | D7: REF2 | E7: YRA1 | G7: 3'end processing | H7: Polyadenylation | I7: Polyadenylation | J7: 3'end processing | K7: Co-transcriptional THO | P7: Co-transcriptional THO | R7: YRA2 | S7: 4 | T7: 0
A8: STO1 | B8: NPL3 | C8: PAB1 | D8: SNU71 | E8: YRA1 | G8: 5'end -CBC | H8: Polyadenylation | I8: Polyadenylation | J8: Splicing | K8: Co-transcriptional THO | P8: Splicing | Q8: Splicing | R8: SNU71 | S8: 13 | T8: 4
A9: GFD1 | B9: NPL3 | C9: PAB1 | D9: SNU71 | E9: YRA1 | G9: Polyadenylation | H9: Polyadenylation | I9: Polyadenylation | J9: Splicing | K9: Co-transcriptional THO | P9: Splicing | R9: PRP42 | S9: 7 | T9: 0
A10: MEX67 | B10: NAB2 | C10: PAB1 | D10: SUB2 | E10: YRA1 | G10: Export | H10: Polyadenylation | I10: Polyadenylation | J10: TREX | K10: Co-transcriptional THO | P10: Splicing | R10: SNU114 | S10: 9 | T10: 2
A11: STO1 | B11: NPL3 | C11: PAB1 | D11: THP2 | E11: YRA1 | G11: 5'end -CBC | H11: Polyadenylation | I11: Polyadenylation | J11: Co-transcriptional THO | K11: Co-transcriptional THO | P11: Splicing | R11: PRP6 | S11: 8 | T11: 0
A12: GBP2 | B12: NPL3 | C12: PAB1 | D12: THP2 | E12: YRA1 | G12: Polyadenylation | H12: Polyadenylation | I12: Polyadenylation | J12: Co-transcriptional THO | K12: Co-transcriptional THO | P12: 3'end processing | Q12: 3'end processing | R12: RNA14 | S12: 14 | T12: 0
A13: NPL3 | B13: PAB1 | C13: REF2 | D13: SNU71 | E13: YRA1 | G13: Polyadenylation | H13: Polyadenylation | I13: 3'end processing | J13: Splicing | K13: Co-transcriptional THO | P13: 3'end processing | R13: CLP1 | S13: 15 | T13: 4
A14: CLP1 | B14: HRP1 | C14: PAB1 | D14: REF2 | G14: 3'end processing | H14: 3'end processing | I14: Polyadenylation | J14: 3'end processing | P14: 3'end processing | R14: YSH1 | S14: 14 | T14: 0
A15: STO1 | B15: NPL3 | C15: PAB1 | D15: SNU114 | G15: 5'end -CBC | H15: Polyadenylation | I15: Polyadenylation | J15: Splicing | P15: 3'end processing | R15: HRP1 | S15: 15 | T15: 4
A16: CLP1 | B16: HRP1 | C16: PAB1 | D16: YRA1 | G16: 3'end processing | H16: 3'end processing | I16: Polyadenylation | J16: Co-transcriptional THO | P16: 3'end processing | R16: SYC1 | S16: 4 | T16: 1
A17: GBP2 | B17: HRP1 | C17: PAB1 | D17: YRA1 | G17: Polyadenylation | H17: 3'end processing | I17: Polyadenylation | J17: Co-transcriptional THO | P17: 3'end processing | R17: CFT1 | S17: 14 | T17: 0
A18: HRP1 | B18: PAB1 | C18: REF2 | D18: YRA1 | G18: 3'end processing | H18: Polyadenylation | I18: 3'end processing | J18: Co-transcriptional THO | P18: 3'end processing | R18: REF2 | S18: 19 | T18: 5
A19: PAB1 | B19: REF2 | C19: SYC1 | D19: YRA1 | G19: Polyadenylation | H19: 3'end processing | I19: 3'end processing | J19: Co-transcriptional THO | P19: Polyadenylation | Q19: Polyadenylation | R19: PAB1 | S19: 47 | T19: 20
A20: PAB1 | B20: SUB2 | C20: THP2 | D20: YRA1 | G20: Polyadenylation | H20: TREX | I20: Co-transcriptional THO | J20: Co-transcriptional THO | P20: Polyadenylation | R20: PAP1 | S20: 9 | T20: 0
A21: PAB1 | B21: RRP6 | C21: YRA1 | G21: Polyadenylation | H21: Degradation | I21: Co-transcriptional THO | P21: Polyadenylation | R21: NAB2 | S21: 55 | T21: 5
P22: Polyadenylation | R22: NPL3 | S22: 35 | T22: 10
P23: Polyadenylation | R23: GBP2 | S23: 7 | T23: 2
P24: Polyadenylation | R24: HRB1 | S24: 10 | T24: 0
P25: Polyadenylation | R25: GFD1 | S25: 16 | T25: 3
P26: Degradation | Q26: Degradation | R26: RRP6 | S26: 3 | T26: 1
P27: TREX | Q27: TREX | R27: SUB2 | S27: 21 | T27: 2
P28: Quality control | Q28: Quality control | R28: PML39 | S28: 19 | T28: 0
P29: NPC associated | Q29: NPC associated | R29: SAC3 | S29: 10 | T29: 1
P30: NPC associated | R30: THP1 | S30: 3 | T30: 0
P31: Export | Q31: Export | R31: MTR2 | S31: 4 | T31: 0
P32: Export | R32: MEX67 | S32: 13 | T32: 2
P33: Export | R33: DBP5 | S33: 11 | T33: 2
P34: Export | R34: MLP1 | S34: 13 | T34: 0
P35: Export | R35: MLP2 | S35: 12 | T35: 0
P36: Cytoplasmic mRNPs | Q36: Cytoplasmic mRNPs | R36: SHE2 | S36: 2 | T36: 0
